def plot_model_data(model_out):
    workers = np.array(model_out['workers'])
    wage    = np.array(model_out['wage'])
    wage_premium    = np.array(model_out['wage_premium'])
    city_extent_calc = np.array(model_out['city_extent_calc'])
    p_dot   = np.array(model_out['p_dot'])
    time    = np.arange(len(workers))
   # distance_from_center = np.array(agent_out['distance_from_center'])
   # warranted_price = np.array(agent_out['warranted_price'])

    # Set up the figure with subplots
    fig, axes = plt.subplots(4, 2, figsize=(10, 15))
    fig.suptitle('Model Output', fontsize=16)




-> With my two commented lines uncommented, I get these errors. Commentyin out just # distance_from_center works 
    --------------------------------------------------------------------------
KeyError                                  Traceback (most recent call last)
File ~/anaconda/envs/housing/lib/python3.9/site-packages/pandas/core/indexes/base.py:3629, in Index.get_loc(self, key, method, tolerance)
   3628 try:
-> 3629     return self._engine.get_loc(casted_key)
   3630 except KeyError as err:

File ~/anaconda/envs/housing/lib/python3.9/site-packages/pandas/_libs/index.pyx:136, in pandas._libs.index.IndexEngine.get_loc()

File ~/anaconda/envs/housing/lib/python3.9/site-packages/pandas/_libs/index.pyx:163, in pandas._libs.index.IndexEngine.get_loc()

File pandas/_libs/hashtable_class_helper.pxi:5198, in pandas._libs.hashtable.PyObjectHashTable.get_item()

File pandas/_libs/hashtable_class_helper.pxi:5206, in pandas._libs.hashtable.PyObjectHashTable.get_item()

KeyError: 'distance_from_center'

The above exception was the direct cause of the following exception:

KeyError                                  Traceback (most recent call last)
Cell In[138], line 68
     65     plt.subplots_adjust(top=0.9)
     66     plt.show()
---> 68 plot_model_data(model_out)

Cell In[138], line 8, in plot_model_data(model_out)
      6 p_dot   = np.array(model_out['p_dot'])
      7 time    = np.arange(len(workers))
----> 8 distance_from_center = np.array(agent_out['distance_from_center'])
      9 warranted_price = np.array(agent_out['warranted_price'])
     11 # Set up the figure with subplots

File ~/anaconda/envs/housing/lib/python3.9/site-packages/pandas/core/frame.py:3505, in DataFrame.__getitem__(self, key)
   3503 if self.columns.nlevels > 1:
   3504     return self._getitem_multilevel(key)
-> 3505 indexer = self.columns.get_loc(key)
   3506 if is_integer(indexer):
   3507     indexer = [indexer]

File ~/anaconda/envs/housing/lib/python3.9/site-packages/pandas/core/indexes/base.py:3631, in Index.get_loc(self, key, method, tolerance)
   3629     return self._engine.get_loc(casted_key)
   3630 except KeyError as err:
-> 3631     raise KeyError(key) from err
   3632 except TypeError:
   3633     # If we have a listlike key, _check_indexing_error will raise
   3634     #  InvalidIndexError. Otherwise we fall through and re-raise
   3635     #  the TypeError.
   3636     self._check_indexing_error(key)

KeyError: 'distance_from_center'
